<robot name="2_R_robot">
<material name="blue">
    <color rgba="0 0 0.8 1"/>
  </material>
  <material name="black">
    <color rgba="0 0 0 1"/>
  </material>
  <material name="white">
    <color rgba="1 1 1 1"/>
  </material>
  <material name="red">
    <color rgba="1 0 0 1"/>
  </material>

    <link name="fixed_base">
        <visual>
            <geometry>
                <sphere radius="0.1"/>
            </geometry>
            <material name="white"/>
        </visual>
    </link>
    <link name="link_1">          
        <visual>
            <geometry>
                <box size="1 0.1 0.1"/>
            </geometry>
              <origin xyz="0.5 0.0 0.0" rpy="0.0 0.0 0.0"/>
            <material name="red"/>
            </visual>
    </link>

      <joint name="Revolute_joint_1" type="revolute">
      <limit lower="0.0" upper="0.548" effort="1000.0" velocity="0.5"/>
      <axis xyz="0 1 0"/>
      <parent link="fixed_base"/>
      <child link="link_1"/>
      <origin xyz="0 0 0" rpy="0.0 -0.5 0.0"/>
      </joint>

    

    <link name="link_2">
    <visual>
      <geometry>
        <box size="1 0.1 0.1"/>
      </geometry>
      <origin xyz="0.5 0.0 0.0" rpy="0.0 0.0 0.0"/>
      <material name="blue"/>
    </visual>
    </link>
    

<joint name="Revolute_joint_2" type="revolute">
    <limit effort="1000.0" lower="0.0" upper="0.548" velocity="0.5"/>
    <axis xyz="0 1 0"/>
    <parent link="link_1"/>
    <child link="link_2"/>

    <origin xyz = "1 0 0" rpy="0 -0.7 0"/>

</joint>
</robot>